Workbook

Sheet Uebersicht
A1: Helferstunden-Auswertung
A2: Schlossturmschiessen 2026 · Auswertung der Einsatzliste nach Verein
A3: Datengrundlage: Einsatzliste Schlossturmschiessen 2026 (PDF vom 10.04.2026)
A5: OK-Einsätze mitzählen: | B5: NEIN | C5: JA / NEIN – «NEIN» entspricht der Zählweise im Original-Einsatzplan (OK-Mitglieder separat).
A7: Helferstunden pro Verein
A8: Einsatz | B8: Datum | C8: =IF(Stammdaten!$A$14="","",Stammdaten!$A$14) -> SV F'bach-Pf'kon | D8: =IF(Stammdaten!$A$15="","",Stammdaten!$A$15) -> MSV Wilen | E8: =IF(Stammdaten!$A$16="","",Stammdaten!$A$16) -> SV Wollerau | F8: Total
A9: =IF(Stammdaten!$A4="","",Stammdaten!$A4) -> E1 | B9: =IF(Stammdaten!$A4="","",Stammdaten!$B4) -> 46130 | C9: =IF(OR($A9="",C$8=""),"",SUMIFS(Zuteilungen!$H$2:$H$200,Zuteilungen!$A$2:$A$200,$A9,Zuteilungen!$E$2:$E$200,C$8,Zuteilungen!$F$2:$F$200,"x")+IF($B$5="JA",SUMIFS(Zuteilungen!$H$2:$H$200,Zuteilungen!$A$2:$A$200,$A9,Zuteilungen!$E$2:$E$200,C$8,Zuteilungen!$F$2:$F$200,"OK"),0)) -> 35 | D9: =IF(OR($A9="",D$8=""),"",SUMIFS(Zuteilungen!$H$2:$H$200,Zuteilungen!$A$2:$A$200,$A9,Zuteilungen!$E$2:$E$200,D$8,Zuteilungen!$F$2:$F$200,"x")+IF($B$5="JA",SUMIFS(Zuteilungen!$H$2:$H$200,Zuteilungen!$A$2:$A$200,$A9,Zuteilungen!$E$2:$E$200,D$8,Zuteilungen!$F$2:$F$200,"OK"),0)) -> 35 | E9: =IF(OR($A9="",E$8=""),"",SUMIFS(Zuteilungen!$H$2:$H$200,Zuteilungen!$A$2:$A$200,$A9,Zuteilungen!$E$2:$E$200,E$8,Zuteilungen!$F$2:$F$200,"x")+IF($B$5="JA",SUMIFS(Zuteilungen!$H$2:$H$200,Zuteilungen!$A$2:$A$200,$A9,Zuteilungen!$E$2:$E$200,E$8,Zuteilungen!$F$2:$F$200,"OK"),0)) -> 50 | F9: =IF($A9="","",SUM(C9:E9)) -> 120
A10: =IF(Stammdaten!$A5="","",Stammdaten!$A5) -> E2 | B10: =IF(Stammdaten!$A5="","",Stammdaten!$B5) -> 46130 | C10: =IF(OR($A10="",C$8=""),"",SUMIFS(Zuteilungen!$H$2:$H$200,Zuteilungen!$A$2:$A$200,$A10,Zuteilungen!$E$2:$E$200,C$8,Zuteilungen!$F$2:$F$200,"x")+IF($B$5="JA",SUMIFS(Zuteilungen!$H$2:$H$200,Zuteilungen!$A$2:$A$200,$A10,Zuteilungen!$E$2:$E$200,C$8,Zuteilungen!$F$2:$F$200,"OK"),0)) -> 30 | D10: =IF(OR($A10="",D$8=""),"",SUMIFS(Zuteilungen!$H$2:$H$200,Zuteilungen!$A$2:$A$200,$A10,Zuteilungen!$E$2:$E$200,D$8,Zuteilungen!$F$2:$F$200,"x")+IF($B$5="JA",SUMIFS(Zuteilungen!$H$2:$H$200,Zuteilungen!$A$2:$A$200,$A10,Zuteilungen!$E$2:$E$200,D$8,Zuteilungen!$F$2:$F$200,"OK"),0)) -> 20 | E10: =IF(OR($A10="",E$8=""),"",SUMIFS(Zuteilungen!$H$2:$H$200,Zuteilungen!$A$2:$A$200,$A10,Zuteilungen!$E$2:$E$200,E$8,Zuteilungen!$F$2:$F$200,"x")+IF($B$5="JA",SUMIFS(Zuteilungen!$H$2:$H$200,Zuteilungen!$A$2:$A$200,$A10,Zuteilungen!$E$2:$E$200,E$8,Zuteilungen!$F$2:$F$200,"OK"),0)) -> 45 | F10: =IF($A10="","",SUM(C10:E10)) -> 95
A11: =IF(Stammdaten!$A6="","",Stammdaten!$A6) -> E3 | B11: =IF(Stammdaten!$A6="","",Stammdaten!$B6) -> 46131 | C11: =IF(OR($A11="",C$8=""),"",SUMIFS(Zuteilungen!$H$2:$H$200,Zuteilungen!$A$2:$A$200,$A11,Zuteilungen!$E$2:$E$200,C$8,Zuteilungen!$F$2:$F$200,"x")+IF($B$5="JA",SUMIFS(Zuteilungen!$H$2:$H$200,Zuteilungen!$A$2:$A$200,$A11,Zuteilungen!$E$2:$E$200,C$8,Zuteilungen!$F$2:$F$200,"OK"),0)) -> 15 | D11: =IF(OR($A11="",D$8=""),"",SUMIFS(Zuteilungen!$H$2:$H$200,Zuteilungen!$A$2:$A$200,$A11,Zuteilungen!$E$2:$E$200,D$8,Zuteilungen!$F$2:$F$200,"x")+IF($B$5="JA",SUMIFS(Zuteilungen!$H$2:$H$200,Zuteilungen!$A$2:$A$200,$A11,Zuteilungen!$E$2:$E$200,D$8,Zuteilungen!$F$2:$F$200,"OK"),0)) -> 27 | E11: =IF(OR($A11="",E$8=""),"",SUMIFS(Zuteilungen!$H$2:$H$200,Zuteilungen!$A$2:$A$200,$A11,Zuteilungen!$E$2:$E$200,E$8,Zuteilungen!$F$2:$F$200,"x")+IF($B$5="JA",SUMIFS(Zuteilungen!$H$2:$H$200,Zuteilungen!$A$2:$A$200,$A11,Zuteilungen!$E$2:$E$200,E$8,Zuteilungen!$F$2:$F$200,"OK"),0)) -> 24 | F11: =IF($A11="","",SUM(C11:E11)) -> 66
A12: =IF(Stammdaten!$A7="","",Stammdaten!$A7) -> E4 | B12: =IF(Stammdaten!$A7="","",Stammdaten!$B7) -> 46137 | C12: =IF(OR($A12="",C$8=""),"",SUMIFS(Zuteilungen!$H$2:$H$200,Zuteilungen!$A$2:$A$200,$A12,Zuteilungen!$E$2:$E$200,C$8,Zuteilungen!$F$2:$F$200,"x")+IF($B$5="JA",SUMIFS(Zuteilungen!$H$2:$H$200,Zuteilungen!$A$2:$A$200,$A12,Zuteilungen!$E$2:$E$200,C$8,Zuteilungen!$F$2:$F$200,"OK"),0)) -> 30 | D12: =IF(OR($A12="",D$8=""),"",SUMIFS(Zuteilungen!$H$2:$H$200,Zuteilungen!$A$2:$A$200,$A12,Zuteilungen!$E$2:$E$200,D$8,Zuteilungen!$F$2:$F$200,"x")+IF($B$5="JA",SUMIFS(Zuteilungen!$H$2:$H$200,Zuteilungen!$A$2:$A$200,$A12,Zuteilungen!$E$2:$E$200,D$8,Zuteilungen!$F$2:$F$200,"OK"),0)) -> 20 | E12: =IF(OR($A12="",E$8=""),"",SUMIFS(Zuteilungen!$H$2:$H$200,Zuteilungen!$A$2:$A$200,$A12,Zuteilungen!$E$2:$E$200,E$8,Zuteilungen!$F$2:$F$200,"x")+IF($B$5="JA",SUMIFS(Zuteilungen!$H$2:$H$200,Zuteilungen!$A$2:$A$200,$A12,Zuteilungen!$E$2:$E$200,E$8,Zuteilungen!$F$2:$F$200,"OK"),0)) -> 35 | F12: =IF($A12="","",SUM(C12:E12)) -> 85
A13: =IF(Stammdaten!$A8="","",Stammdaten!$A8) -> E5 | B13: =IF(Stammdaten!$A8="","",Stammdaten!$B8) -> 45773 | C13: =IF(OR($A13="",C$8=""),"",SUMIFS(Zuteilungen!$H$2:$H$200,Zuteilungen!$A$2:$A$200,$A13,Zuteilungen!$E$2:$E$200,C$8,Zuteilungen!$F$2:$F$200,"x")+IF($B$5="JA",SUMIFS(Zuteilungen!$H$2:$H$200,Zuteilungen!$A$2:$A$200,$A13,Zuteilungen!$E$2:$E$200,C$8,Zuteilungen!$F$2:$F$200,"OK"),0)) -> 0 | D13: =IF(OR($A13="",D$8=""),"",SUMIFS(Zuteilungen!$H$2:$H$200,Zuteilungen!$A$2:$A$200,$A13,Zuteilungen!$E$2:$E$200,D$8,Zuteilungen!$F$2:$F$200,"x")+IF($B$5="JA",SUMIFS(Zuteilungen!$H$2:$H$200,Zuteilungen!$A$2:$A$200,$A13,Zuteilungen!$E$2:$E$200,D$8,Zuteilungen!$F$2:$F$200,"OK"),0)) -> 0 | E13: =IF(OR($A13="",E$8=""),"",SUMIFS(Zuteilungen!$H$2:$H$200,Zuteilungen!$A$2:$A$200,$A13,Zuteilungen!$E$2:$E$200,E$8,Zuteilungen!$F$2:$F$200,"x")+IF($B$5="JA",SUMIFS(Zuteilungen!$H$2:$H$200,Zuteilungen!$A$2:$A$200,$A13,Zuteilungen!$E$2:$E$200,E$8,Zuteilungen!$F$2:$F$200,"OK"),0)) -> 5 | F13: =IF($A13="","",SUM(C13:E13)) -> 5
A14: =IF(Stammdaten!$A9="","",Stammdaten!$A9) | B14: =IF(Stammdaten!$A9="","",Stammdaten!$B9) | C14: =IF(OR($A14="",C$8=""),"",SUMIFS(Zuteilungen!$H$2:$H$200,Zuteilungen!$A$2:$A$200,$A14,Zuteilungen!$E$2:$E$200,C$8,Zuteilungen!$F$2:$F$200,"x")+IF($B$5="JA",SUMIFS(Zuteilungen!$H$2:$H$200,Zuteilungen!$A$2:$A$200,$A14,Zuteilungen!$E$2:$E$200,C$8,Zuteilungen!$F$2:$F$200,"OK"),0)) | D14: =IF(OR($A14="",D$8=""),"",SUMIFS(Zuteilungen!$H$2:$H$200,Zuteilungen!$A$2:$A$200,$A14,Zuteilungen!$E$2:$E$200,D$8,Zuteilungen!$F$2:$F$200,"x")+IF($B$5="JA",SUMIFS(Zuteilungen!$H$2:$H$200,Zuteilungen!$A$2:$A$200,$A14,Zuteilungen!$E$2:$E$200,D$8,Zuteilungen!$F$2:$F$200,"OK"),0)) | E14: =IF(OR($A14="",E$8=""),"",SUMIFS(Zuteilungen!$H$2:$H$200,Zuteilungen!$A$2:$A$200,$A14,Zuteilungen!$E$2:$E$200,E$8,Zuteilungen!$F$2:$F$200,"x")+IF($B$5="JA",SUMIFS(Zuteilungen!$H$2:$H$200,Zuteilungen!$A$2:$A$200,$A14,Zuteilungen!$E$2:$E$200,E$8,Zuteilungen!$F$2:$F$200,"OK"),0)) | F14: =IF($A14="","",SUM(C14:E14))
A15: Total | C15: =SUM(C9:C14) -> 110 | D15: =SUM(D9:D14) -> 102 | E15: =SUM(E9:E14) -> 159 | F15: =SUM(F9:F14) -> 371
A18: Anzahl Einsätze (Helfer-Positionen) pro Verein
A19: Einsatz | B19: Datum | C19: =IF(Stammdaten!$A$14="","",Stammdaten!$A$14) -> SV F'bach-Pf'kon | D19: =IF(Stammdaten!$A$15="","",Stammdaten!$A$15) -> MSV Wilen | E19: =IF(Stammdaten!$A$16="","",Stammdaten!$A$16) -> SV Wollerau | F19: Total
A20: =IF(Stammdaten!$A4="","",Stammdaten!$A4) -> E1 | B20: =IF(Stammdaten!$A4="","",Stammdaten!$B4) -> 46130 | C20: =IF(OR($A20="",C$19=""),"",COUNTIFS(Zuteilungen!$A$2:$A$200,$A20,Zuteilungen!$E$2:$E$200,C$19,Zuteilungen!$F$2:$F$200,"x")+IF($B$5="JA",COUNTIFS(Zuteilungen!$A$2:$A$200,$A20,Zuteilungen!$E$2:$E$200,C$19,Zuteilungen!$F$2:$F$200,"OK"),0)) -> 7 | D20: =IF(OR($A20="",D$19=""),"",COUNTIFS(Zuteilungen!$A$2:$A$200,$A20,Zuteilungen!$E$2:$E$200,D$19,Zuteilungen!$F$2:$F$200,"x")+IF($B$5="JA",COUNTIFS(Zuteilungen!$A$2:$A$200,$A20,Zuteilungen!$E$2:$E$200,D$19,Zuteilungen!$F$2:$F$200,"OK"),0)) -> 7 | E20: =IF(OR($A20="",E$19=""),"",COUNTIFS(Zuteilungen!$A$2:$A$200,$A20,Zuteilungen!$E$2:$E$200,E$19,Zuteilungen!$F$2:$F$200,"x")+IF($B$5="JA",COUNTIFS(Zuteilungen!$A$2:$A$200,$A20,Zuteilungen!$E$2:$E$200,E$19,Zuteilungen!$F$2:$F$200,"OK"),0)) -> 10 | F20: =IF($A20="","",SUM(C20:E20)) -> 24
A21: =IF(Stammdaten!$A5="","",Stammdaten!$A5) -> E2 | B21: =IF(Stammdaten!$A5="","",Stammdaten!$B5) -> 46130 | C21: =IF(OR($A21="",C$19=""),"",COUNTIFS(Zuteilungen!$A$2:$A$200,$A21,Zuteilungen!$E$2:$E$200,C$19,Zuteilungen!$F$2:$F$200,"x")+IF($B$5="JA",COUNTIFS(Zuteilungen!$A$2:$A$200,$A21,Zuteilungen!$E$2:$E$200,C$19,Zuteilungen!$F$2:$F$200,"OK"),0)) -> 6 | D21: =IF(OR($A21="",D$19=""),"",COUNTIFS(Zuteilungen!$A$2:$A$200,$A21,Zuteilungen!$E$2:$E$200,D$19,Zuteilungen!$F$2:$F$200,"x")+IF($B$5="JA",COUNTIFS(Zuteilungen!$A$2:$A$200,$A21,Zuteilungen!$E$2:$E$200,D$19,Zuteilungen!$F$2:$F$200,"OK"),0)) -> 4 | E21: =IF(OR($A21="",E$19=""),"",COUNTIFS(Zuteilungen!$A$2:$A$200,$A21,Zuteilungen!$E$2:$E$200,E$19,Zuteilungen!$F$2:$F$200,"x")+IF($B$5="JA",COUNTIFS(Zuteilungen!$A$2:$A$200,$A21,Zuteilungen!$E$2:$E$200,E$19,Zuteilungen!$F$2:$F$200,"OK"),0)) -> 9 | F21: =IF($A21="","",SUM(C21:E21)) -> 19
A22: =IF(Stammdaten!$A6="","",Stammdaten!$A6) -> E3 | B22: =IF(Stammdaten!$A6="","",Stammdaten!$B6) -> 46131 | C22: =IF(OR($A22="",C$19=""),"",COUNTIFS(Zuteilungen!$A$2:$A$200,$A22,Zuteilungen!$E$2:$E$200,C$19,Zuteilungen!$F$2:$F$200,"x")+IF($B$5="JA",COUNTIFS(Zuteilungen!$A$2:$A$200,$A22,Zuteilungen!$E$2:$E$200,C$19,Zuteilungen!$F$2:$F$200,"OK"),0)) -> 5 | D22: =IF(OR($A22="",D$19=""),"",COUNTIFS(Zuteilungen!$A$2:$A$200,$A22,Zuteilungen!$E$2:$E$200,D$19,Zuteilungen!$F$2:$F$200,"x")+IF($B$5="JA",COUNTIFS(Zuteilungen!$A$2:$A$200,$A22,Zuteilungen!$E$2:$E$200,D$19,Zuteilungen!$F$2:$F$200,"OK"),0)) -> 9 | E22: =IF(OR($A22="",E$19=""),"",COUNTIFS(Zuteilungen!$A$2:$A$200,$A22,Zuteilungen!$E$2:$E$200,E$19,Zuteilungen!$F$2:$F$200,"x")+IF($B$5="JA",COUNTIFS(Zuteilungen!$A$2:$A$200,$A22,Zuteilungen!$E$2:$E$200,E$19,Zuteilungen!$F$2:$F$200,"OK"),0)) -> 8 | F22: =IF($A22="","",SUM(C22:E22)) -> 22
A23: =IF(Stammdaten!$A7="","",Stammdaten!$A7) -> E4 | B23: =IF(Stammdaten!$A7="","",Stammdaten!$B7) -> 46137 | C23: =IF(OR($A23="",C$19=""),"",COUNTIFS(Zuteilungen!$A$2:$A$200,$A23,Zuteilungen!$E$2:$E$200,C$19,Zuteilungen!$F$2:$F$200,"x")+IF($B$5="JA",COUNTIFS(Zuteilungen!$A$2:$A$200,$A23,Zuteilungen!$E$2:$E$200,C$19,Zuteilungen!$F$2:$F$200,"OK"),0)) -> 6 | D23: =IF(OR($A23="",D$19=""),"",COUNTIFS(Zuteilungen!$A$2:$A$200,$A23,Zuteilungen!$E$2:$E$200,D$19,Zuteilungen!$F$2:$F$200,"x")+IF($B$5="JA",COUNTIFS(Zuteilungen!$A$2:$A$200,$A23,Zuteilungen!$E$2:$E$200,D$19,Zuteilungen!$F$2:$F$200,"OK"),0)) -> 4 | E23: =IF(OR($A23="",E$19=""),"",COUNTIFS(Zuteilungen!$A$2:$A$200,$A23,Zuteilungen!$E$2:$E$200,E$19,Zuteilungen!$F$2:$F$200,"x")+IF($B$5="JA",COUNTIFS(Zuteilungen!$A$2:$A$200,$A23,Zuteilungen!$E$2:$E$200,E$19,Zuteilungen!$F$2:$F$200,"OK"),0)) -> 7 | F23: =IF($A23="","",SUM(C23:E23)) -> 17
A24: =IF(Stammdaten!$A8="","",Stammdaten!$A8) -> E5 | B24: =IF(Stammdaten!$A8="","",Stammdaten!$B8) -> 45773 | C24: =IF(OR($A24="",C$19=""),"",COUNTIFS(Zuteilungen!$A$2:$A$200,$A24,Zuteilungen!$E$2:$E$200,C$19,Zuteilungen!$F$2:$F$200,"x")+IF($B$5="JA",COUNTIFS(Zuteilungen!$A$2:$A$200,$A24,Zuteilungen!$E$2:$E$200,C$19,Zuteilungen!$F$2:$F$200,"OK"),0)) -> 0 | D24: =IF(OR($A24="",D$19=""),"",COUNTIFS(Zuteilungen!$A$2:$A$200,$A24,Zuteilungen!$E$2:$E$200,D$19,Zuteilungen!$F$2:$F$200,"x")+IF($B$5="JA",COUNTIFS(Zuteilungen!$A$2:$A$200,$A24,Zuteilungen!$E$2:$E$200,D$19,Zuteilungen!$F$2:$F$200,"OK"),0)) -> 0 | E24: =IF(OR($A24="",E$19=""),"",COUNTIFS(Zuteilungen!$A$2:$A$200,$A24,Zuteilungen!$E$2:$E$200,E$19,Zuteilungen!$F$2:$F$200,"x")+IF($B$5="JA",COUNTIFS(Zuteilungen!$A$2:$A$200,$A24,Zuteilungen!$E$2:$E$200,E$19,Zuteilungen!$F$2:$F$200,"OK"),0)) -> 1 | F24: =IF($A24="","",SUM(C24:E24)) -> 1
A25: =IF(Stammdaten!$A9="","",Stammdaten!$A9) | B25: =IF(Stammdaten!$A9="","",Stammdaten!$B9) | C25: =IF(OR($A25="",C$19=""),"",COUNTIFS(Zuteilungen!$A$2:$A$200,$A25,Zuteilungen!$E$2:$E$200,C$19,Zuteilungen!$F$2:$F$200,"x")+IF($B$5="JA",COUNTIFS(Zuteilungen!$A$2:$A$200,$A25,Zuteilungen!$E$2:$E$200,C$19,Zuteilungen!$F$2:$F$200,"OK"),0)) | D25: =IF(OR($A25="",D$19=""),"",COUNTIFS(Zuteilungen!$A$2:$A$200,$A25,Zuteilungen!$E$2:$E$200,D$19,Zuteilungen!$F$2:$F$200,"x")+IF($B$5="JA",COUNTIFS(Zuteilungen!$A$2:$A$200,$A25,Zuteilungen!$E$2:$E$200,D$19,Zuteilungen!$F$2:$F$200,"OK"),0)) | E25: =IF(OR($A25="",E$19=""),"",COUNTIFS(Zuteilungen!$A$2:$A$200,$A25,Zuteilungen!$E$2:$E$200,E$19,Zuteilungen!$F$2:$F$200,"x")+IF($B$5="JA",COUNTIFS(Zuteilungen!$A$2:$A$200,$A25,Zuteilungen!$E$2:$E$200,E$19,Zuteilungen!$F$2:$F$200,"OK"),0)) | F25: =IF($A25="","",SUM(C25:E25))
A26: Total | C26: =SUM(C20:C25) -> 24 | D26: =SUM(D20:D25) -> 24 | E26: =SUM(E20:E25) -> 35 | F26: =SUM(F20:F25) -> 83
A29: Gesamtabrechnung pro Verein
A30: Position | C30: =IF(Stammdaten!$A$14="","",Stammdaten!$A$14) -> SV F'bach-Pf'kon | D30: =IF(Stammdaten!$A$15="","",Stammdaten!$A$15) -> MSV Wilen | E30: =IF(Stammdaten!$A$16="","",Stammdaten!$A$16) -> SV Wollerau | F30: Total
A31: Einsätze gemäss Einsatzliste | C31: =IF(C$8="","",C15) -> 110 | D31: =IF(D$8="","",D15) -> 102 | E31: =IF(E$8="","",E15) -> 159 | F31: =F15 -> 371
A32: Diverse Vor- & Nacharbeiten | C32: =IF(C$30="","",SUMIFS('Vor- und Nacharbeiten'!$D$5:$D$64,'Vor- und Nacharbeiten'!$C$5:$C$64,C$30,'Vor- und Nacharbeiten'!$E$5:$E$64,"x")+IF($B$5="JA",SUMIFS('Vor- und Nacharbeiten'!$D$5:$D$64,'Vor- und Nacharbeiten'!$C$5:$C$64,C$30,'Vor- und Nacharbeiten'!$E$5:$E$64,"OK"),0)) -> 108 | D32: =IF(D$30="","",SUMIFS('Vor- und Nacharbeiten'!$D$5:$D$64,'Vor- und Nacharbeiten'!$C$5:$C$64,D$30,'Vor- und Nacharbeiten'!$E$5:$E$64,"x")+IF($B$5="JA",SUMIFS('Vor- und Nacharbeiten'!$D$5:$D$64,'Vor- und Nacharbeiten'!$C$5:$C$64,D$30,'Vor- und Nacharbeiten'!$E$5:$E$64,"OK"),0)) -> 103 | E32: =IF(E$30="","",SUMIFS('Vor- und Nacharbeiten'!$D$5:$D$64,'Vor- und Nacharbeiten'!$C$5:$C$64,E$30,'Vor- und Nacharbeiten'!$E$5:$E$64,"x")+IF($B$5="JA",SUMIFS('Vor- und Nacharbeiten'!$D$5:$D$64,'Vor- und Nacharbeiten'!$C$5:$C$64,E$30,'Vor- und Nacharbeiten'!$E$5:$E$64,"OK"),0)) -> 62 | F32: =SUM(C32:E32) -> 273
A33: Total Helferstunden | C33: =N(C31)+N(C32) -> 218 | D33: =N(D31)+N(D32) -> 205 | E33: =N(E31)+N(E32) -> 221 | F33: =N(F31)+N(F32) -> 644
A34: Anteil in % | C34: =IF($F33=0,"",C33/$F33) -> 0.33850932 | D34: =IF($F33=0,"",D33/$F33) -> 0.31832298 | E34: =IF($F33=0,"",E33/$F33) -> 0.3431677 | F34: =IF($F33=0,"",F33/$F33) -> 1
A37: Kennzahlen
A38: Helferstunden total (alle Vereine) | C38: =IF(F15="",0,F15) -> 371
A39: Einsätze total (Helfer-Positionen) | C39: =F26 -> 83
A40: Davon mit Status "OK" (Organisationskomitee) | C40: =COUNTIFS(Zuteilungen!$F$2:$F$200,"OK") -> 15
A41: Stunden der OK-Einsätze | C41: =SUMIFS(Zuteilungen!$H$2:$H$200,Zuteilungen!$F$2:$F$200,"OK") -> 65
A42: Noch offene Positionen (ohne Status) | C42: =COUNTIFS(Zuteilungen!$D$2:$D$200,"<>",Zuteilungen!$F$2:$F$200,"") -> 0
A43: Stunden Vor- & Nacharbeiten | C43: =N(F32) -> 273
A44: Zeilen mit Kommentar / Korrektur | C44: =COUNTIFS(Zuteilungen!$D$2:$D$200,"<>",Zuteilungen!$I$2:$I$200,"<>") -> 1
A47: So ergänzt du manuell
A48: Gelb hinterlegte Zellen sind Eingabefelder – alles andere rechnet sich automatisch.
A49: Neue Helfer erfassen: Blatt «Zuteilungen», erste freie Zeile ausfüllen. Beispiel:
A50: Einsatz-ID = E2 | Funktion = Warner | Name = Muster Hans | Verein = MSV Wilen | Status = x
...

Sheet Original PDF
A1: Original-Einsatzliste (Abbild des PDF)
A2: 1:1-Abbild der Einsatzliste Schlossturmschiessen 2026 zur manuellen Kontrolle. Dieses Blatt enthält keine Auswertungslogik – ausgewertet wird das Blatt «Zuteilungen».
A4: Datum | B4: Samstag, 18.04.2026 | F4: Samstag, 18.04.2026 | J4: Sonntag, 19.04.2026 | N4: Samstag, 25.04.2026
A5: Zeit | B5: 08.00 – 12.00 Uhr | F5: 13.30 – 17.00 Uhr | J5: 09.30 – 11.30 Uhr | N5: 08.00 – 12.00 Uhr
A6: Treffpunkt | B6: 07.30 Uhr (Büro 07.15) | F6: 13.15 Uhr (Büro 13.00) | J6: 09.00 Uhr (Büro 08.45) | N6: 07.30 Uhr (Büro 07.15)
A7: Funktion | B7: Name / Vorname | C7: F'bach-Pf'kon | D7: Wilen | E7: Wollerau | F7: Name / Vorname | G7: F'bach-Pf'kon | H7: Wilen | I7: Wollerau | J7: Name / Vorname | K7: F'bach-Pf'kon | L7: Wilen | M7: Wollerau | N7: Name / Vorname | O7: F'bach-Pf'kon | P7: Wilen | Q7: Wollerau
A8: Parkdienst | B8: Schuler René | E8: x | F8: Schuler René | I8: x | J8: Schuler René | M8: x | N8: Schuler René | Q8: x
A9: Parkdienst | B9: Schuler Karl | C9: x | F9: Ott Arthur | I9: x | J9: Ott Arthur | M9: x
A10: Parkdienst | B10: Bernd Daniel | E10: x | F10: Bernd Daniel | I10: x
A12: Türkontrolle | B12: Dubach Urs | E12: x | F12: Dubach Urs | I12: x | J12: Schuler Karl | K12: x | N12: Schuler Karl | O12: x
A14: Standblätter | B14: Fuchs Marcel | E14: x | F14: Bürgi Adrian | I14: x | J14: Fuchs Michael | L14: x | N14: Fuchs Marcel | Q14: x
A15: Kasse | B15: Schober Hanspeter | D15: x | F15: Schober Hanspeter | H15: x | J15: Lanelli Philipp | K15: OK | N15: Lanelli Philipp | O15: OK
A16: Munition | B16: Kobel Stefan | E16: x | F16: Kobel Stefan | I16: x | J16: Kobel Stefan | M16: x | N16: Sturzenegger Robert | P16: x
A17: Auszahlung | B17: Odermatt Marcel | C17: x | F17: Odermatt Marcel | G17: x | J17: Steinegger Josef | M17: x | N17: Schuler Werner | O17: OK
A18: Auszeichnungen | B18: Pargätzi Bruna | C18: OK | F18: Fuchs Armin | I18: x | J18: Reuteler Pascal | M18: x | N18: Reuteler Pascal | Q18: ?
A20: EDV / Anlage | B20: Linggi Renato | D20: OK | F20: Linggi Renato | H20: OK | J20: Linggi Renato | L20: OK | N20: Linggi Renato | P20: OK
A21: Schiessleitung | B21: Linggi Andreas | D21: OK | F21: Linggi Andreas | H21: OK | J21: Linggi Andreas | L21: OK | N21: Linggi Andreas | P21: OK
A22: Schützenmeister | B22: Schmucki Marco | E22: x | F22: Schmucki Marco | I22: x | J22: Thomi Ivo | L22: x | N22: Flühler Beat | O22: x
A23: Schützenmeister | B23: von Euw Stefan | D23: x | J23: Lienert Roman | L23: x | N23: Lienert Roman | P23: x
A24: Schützenmeister | B24: von Euw Alexander | D24: x | J24: Kälin Norbert | L24: x
A26: Kurier | B26: Linggi Renato | D26: OK | F26: Unterkofler Mark | H26: x | J26: Lienert Elin | L26: x | N26: Lienert Elin | P26: x
A27: Znüni / Zvieri | B27: Flühler Georges | C27: x | F27: Flühler Georges | G27: x | J27: Flühler Georges | K27: x | N27: Flühler Georges | O27: x
A28: Znüni / Zvieri | B28: Wyler Hanspeter | C28: x | F28: Wyler Hanspeter | G28: x | J28: Strickler Julius | K28: x | N28: Strickler Julius | O28: x
A30: Warner | B30: Blättler Renata | E30: x | F30: Blättler Renata | I30: x | J30: Kälin Joshua | L30: x | N30: Zimmermann Jack | O30: x
A31: Warner | B31: König Marcus | D31: x | F31: König Marcus | H31: x | J31: König Marcus | L31: x | N31: König Marcus | P31: x
A32: Warner | B32: Weinen Ingo | D32: x | F32: Weinen Ingo | H32: x | J32: Weinen Ingo | L32: x | N32: Schuler Walter | Q32: x
A33: Warner | B33: Graden Rolf | C33: x | F33: Graden Rolf | G33: x | J33: Schuler Walter | M33: x | N33: Gerber Guido | Q33: x
A34: Warner | B34: Jehli Christian | C34: x | F34: Jehli Christian | G34: x | J34: Gerber Guido | M34: x | N34: Jehli Christian | O34: x
A35: Warner | B35: Steiner Alfred | C35: x | F35: Steiner Alfred | G35: x | J35: Steiner Alfred | K35: x | N35: Betschart Sabrina | Q35: x
A36: Warner | B36: von Euw Judith | D36: x | J36: von Euw Judith | L36: x | N36: Bürgi Roland | Q36: x
A37: Warner | B37: Bürgi Roland | E37: x | J37: Bürgi Roland | M37: x
A38: Warner | B38: Betschart Sabrina | E38: x | J38: Wyler Hanspeter | K38: x
A39: Warner | B39: Steinegger Josef | E39: x | J39: Pargätzi Bruna | M39: OK
A40: Warner | B40: Unterkofler Mark | D40: x | J40: Schuler Werner | K40: OK
A42: Total «x» in diesem Blatt | C42: =COUNTIF(C8:C40,"x") -> 7 | D42: =COUNTIF(D8:D40,"x") -> 7 | E42: =COUNTIF(E8:E40,"x") -> 10 | G42: =COUNTIF(G8:G40,"x") -> 6 | H42: =COUNTIF(H8:H40,"x") -> 4 | I42: =COUNTIF(I8:I40,"x") -> 9 | K42: =COUNTIF(K8:K40,"x") -> 5 | L42: =COUNTIF(L8:L40,"x") -> 9 | M42: =COUNTIF(M8:M40,"x") -> 8 | O42: =COUNTIF(O8:O40,"x") -> 6 | P42: =COUNTIF(P8:P40,"x") -> 4 | Q42: =COUNTIF(Q8:Q40,"x") -> 6
A43: Total gemäss PDF (Kontrollzeile) | C43: 7 | D43: 7 | E43: 10 | G43: 6 | H43: 4 | I43: 9 | K43: 5 | L43: 9 | M43: 8 | O43: 6 | P43: 4 | Q43: 6
A44: Differenz (muss 0 sein) | C44: =C42-C43 -> 0 | D44: =D42-D43 -> 0 | E44: =E42-E43 -> 0 | G44: =G42-G43 -> 0 | H44: =H42-H43 -> 0 | I44: =I42-I43 -> 0 | K44: =K42-K43 -> 0 | L44: =L42-L43 -> 0 | M44: =M42-M43 -> 0 | O44: =O42-O43 -> 0 | P44: =P42-P43 -> 0 | Q44: =Q42-Q43 -> 0
A46: Abgleich mit Blatt «Zuteilungen» | C46: =COUNTIFS(Zuteilungen!$A$2:$A$200,"E1",Zuteilungen!$E$2:$E$200,Stammdaten!$A$14,Zuteilungen!$F$2:$F$200,"x") -> 7 | D46: =COUNTIFS(Zuteilungen!$A$2:$A$200,"E1",Zuteilungen!$E$2:$E$200,Stammdaten!$A$15,Zuteilungen!$F$2:$F$200,"x") -> 7 | E46: =COUNTIFS(Zuteilungen!$A$2:$A$200,"E1",Zuteilungen!$E$2:$E$200,Stammdaten!$A$16,Zuteilungen!$F$2:$F$200,"x") -> 10 | G46: =COUNTIFS(Zuteilungen!$A$2:$A$200,"E2",Zuteilungen!$E$2:$E$200,Stammdaten!$A$14,Zuteilungen!$F$2:$F$200,"x") -> 6 | H46: =COUNTIFS(Zuteilungen!$A$2:$A$200,"E2",Zuteilungen!$E$2:$E$200,Stammdaten!$A$15,Zuteilungen!$F$2:$F$200,"x") -> 4 | I46: =COUNTIFS(Zuteilungen!$A$2:$A$200,"E2",Zuteilungen!$E$2:$E$200,Stammdaten!$A$16,Zuteilungen!$F$2:$F$200,"x") -> 9 | K46: =COUNTIFS(Zuteilungen!$A$2:$A$200,"E3",Zuteilungen!$E$2:$E$200,Stammdaten!$A$14,Zuteilungen!$F$2:$F$200,"x") -> 5 | L46: =COUNTIFS(Zuteilungen!$A$2:$A$200,"E3",Zuteilungen!$E$2:$E$200,Stammdaten!$A$15,Zuteilungen!$F$2:$F$200,"x") -> 9 | M46: =COUNTIFS(Zuteilungen!$A$2:$A$200,"E3",Zuteilungen!$E$2:$E$200,Stammdaten!$A$16,Zuteilungen!$F$2:$F$200,"x") -> 8 | O46: =COUNTIFS(Zuteilungen!$A$2:$A$200,"E4",Zuteilungen!$E$2:$E$200,Stammdaten!$A$14,Zuteilungen!$F$2:$F$200,"x") -> 6 | P46: =COUNTIFS(Zuteilungen!$A$2:$A$200,"E4",Zuteilungen!$E$2:$E$200,Stammdaten!$A$15,Zuteilungen!$F$2:$F$200,"x") -> 4 | Q46: =COUNTIFS(Zuteilungen!$A$2:$A$200,"E4",Zuteilungen!$E$2:$E$200,Stammdaten!$A$16,Zuteilungen!$F$2:$F$200,"x") -> 7
A48: Legende: «x» = regulärer Helfer · «OK» = Mitglied Organisationskomitee · rotes «?» = im PDF ohne Markierung.
A49: Die Zeile «Abgleich» zählt dieselben Einsätze im Blatt «Zuteilungen» – sie muss mit der Zeile «Total «x» in diesem Blatt» übereinstimmen.

Sheet Zuteilungen
A1: Einsatz-ID | B1: Datum | C1: Funktion | D1: Name / Vorname | E1: Verein | F1: Status | G1: Stunden manuell | H1: Stunden | I1: Bemerkung / Kommentar | J1: Korr-Nr
A2: E1 | B2: =IF($A2="","",IFERROR(INDEX(Stammdaten!$B$4:$B$9,MATCH($A2,Stammdaten!$A$4:$A$9,0)),"")) -> 46130 | C2: Parkdienst | D2: Schuler René | E2: SV Wollerau | F2: x | H2: =IF($D2="","",IF($F2="",0,IF($G2<>"",$G2,IFERROR(INDEX(Stammdaten!$G$4:$G$9,MATCH($A2,Stammdaten!$A$4:$A$9,0)),0)))) -> 5 | J2: =IF(AND($D2<>"",$I2<>""),COUNTIFS($D$2:$D2,"<>",$I$2:$I2,"<>"),"")
A3: E2 | B3: =IF($A3="","",IFERROR(INDEX(Stammdaten!$B$4:$B$9,MATCH($A3,Stammdaten!$A$4:$A$9,0)),"")) -> 46130 | C3: Parkdienst | D3: Schuler René | E3: SV Wollerau | F3: x | H3: =IF($D3="","",IF($F3="",0,IF($G3<>"",$G3,IFERROR(INDEX(Stammdaten!$G$4:$G$9,MATCH($A3,Stammdaten!$A$4:$A$9,0)),0)))) -> 5 | J3: =IF(AND($D3<>"",$I3<>""),COUNTIFS($D$2:$D3,"<>",$I$2:$I3,"<>"),"")
A4: E3 | B4: =IF($A4="","",IFERROR(INDEX(Stammdaten!$B$4:$B$9,MATCH($A4,Stammdaten!$A$4:$A$9,0)),"")) -> 46131 | C4: Parkdienst | D4: Schuler René | E4: SV Wollerau | F4: x | H4: =IF($D4="","",IF($F4="",0,IF($G4<>"",$G4,IFERROR(INDEX(Stammdaten!$G$4:$G$9,MATCH($A4,Stammdaten!$A$4:$A$9,0)),0)))) -> 3 | J4: =IF(AND($D4<>"",$I4<>""),COUNTIFS($D$2:$D4,"<>",$I$2:$I4,"<>"),"")
A5: E4 | B5: =IF($A5="","",IFERROR(INDEX(Stammdaten!$B$4:$B$9,MATCH($A5,Stammdaten!$A$4:$A$9,0)),"")) -> 46137 | C5: Parkdienst | D5: Schuler René | E5: SV Wollerau | F5: x | H5: =IF($D5="","",IF($F5="",0,IF($G5<>"",$G5,IFERROR(INDEX(Stammdaten!$G$4:$G$9,MATCH($A5,Stammdaten!$A$4:$A$9,0)),0)))) -> 5 | J5: =IF(AND($D5<>"",$I5<>""),COUNTIFS($D$2:$D5,"<>",$I$2:$I5,"<>"),"")
A6: E1 | B6: =IF($A6="","",IFERROR(INDEX(Stammdaten!$B$4:$B$9,MATCH($A6,Stammdaten!$A$4:$A$9,0)),"")) -> 46130 | C6: Parkdienst | D6: Schuler Karl | E6: SV F'bach-Pf'kon | F6: x | H6: =IF($D6="","",IF($F6="",0,IF($G6<>"",$G6,IFERROR(INDEX(Stammdaten!$G$4:$G$9,MATCH($A6,Stammdaten!$A$4:$A$9,0)),0)))) -> 5 | J6: =IF(AND($D6<>"",$I6<>""),COUNTIFS($D$2:$D6,"<>",$I$2:$I6,"<>"),"")
A7: E2 | B7: =IF($A7="","",IFERROR(INDEX(Stammdaten!$B$4:$B$9,MATCH($A7,Stammdaten!$A$4:$A$9,0)),"")) -> 46130 | C7: Parkdienst | D7: Ott Arthur | E7: SV Wollerau | F7: x | H7: =IF($D7="","",IF($F7="",0,IF($G7<>"",$G7,IFERROR(INDEX(Stammdaten!$G$4:$G$9,MATCH($A7,Stammdaten!$A$4:$A$9,0)),0)))) -> 5 | J7: =IF(AND($D7<>"",$I7<>""),COUNTIFS($D$2:$D7,"<>",$I$2:$I7,"<>"),"")
A8: E3 | B8: =IF($A8="","",IFERROR(INDEX(Stammdaten!$B$4:$B$9,MATCH($A8,Stammdaten!$A$4:$A$9,0)),"")) -> 46131 | C8: Parkdienst | D8: Ott Arthur | E8: SV Wollerau | F8: x | H8: =IF($D8="","",IF($F8="",0,IF($G8<>"",$G8,IFERROR(INDEX(Stammdaten!$G$4:$G$9,MATCH($A8,Stammdaten!$A$4:$A$9,0)),0)))) -> 3 | J8: =IF(AND($D8<>"",$I8<>""),COUNTIFS($D$2:$D8,"<>",$I$2:$I8,"<>"),"")
A9: E1 | B9: =IF($A9="","",IFERROR(INDEX(Stammdaten!$B$4:$B$9,MATCH($A9,Stammdaten!$A$4:$A$9,0)),"")) -> 46130 | C9: Parkdienst | D9: Bernd Daniel | E9: SV Wollerau | F9: x | H9: =IF($D9="","",IF($F9="",0,IF($G9<>"",$G9,IFERROR(INDEX(Stammdaten!$G$4:$G$9,MATCH($A9,Stammdaten!$A$4:$A$9,0)),0)))) -> 5 | J9: =IF(AND($D9<>"",$I9<>""),COUNTIFS($D$2:$D9,"<>",$I$2:$I9,"<>"),"")
A10: E2 | B10: =IF($A10="","",IFERROR(INDEX(Stammdaten!$B$4:$B$9,MATCH($A10,Stammdaten!$A$4:$A$9,0)),"")) -> 46130 | C10: Parkdienst | D10: Bernd Daniel | E10: SV Wollerau | F10: x | H10: =IF($D10="","",IF($F10="",0,IF($G10<>"",$G10,IFERROR(INDEX(Stammdaten!$G$4:$G$9,MATCH($A10,Stammdaten!$A$4:$A$9,0)),0)))) -> 5 | J10: =IF(AND($D10<>"",$I10<>""),COUNTIFS($D$2:$D10,"<>",$I$2:$I10,"<>"),"")
A11: E1 | B11: =IF($A11="","",IFERROR(INDEX(Stammdaten!$B$4:$B$9,MATCH($A11,Stammdaten!$A$4:$A$9,0)),"")) -> 46130 | C11: Türkontrolle | D11: Dubach Urs | E11: SV Wollerau | F11: x | H11: =IF($D11="","",IF($F11="",0,IF($G11<>"",$G11,IFERROR(INDEX(Stammdaten!$G$4:$G$9,MATCH($A11,Stammdaten!$A$4:$A$9,0)),0)))) -> 5 | J11: =IF(AND($D11<>"",$I11<>""),COUNTIFS($D$2:$D11,"<>",$I$2:$I11,"<>"),"")
A12: E2 | B12: =IF($A12="","",IFERROR(INDEX(Stammdaten!$B$4:$B$9,MATCH($A12,Stammdaten!$A$4:$A$9,0)),"")) -> 46130 | C12: Türkontrolle | D12: Dubach Urs | E12: SV Wollerau | F12: x | H12: =IF($D12="","",IF($F12="",0,IF($G12<>"",$G12,IFERROR(INDEX(Stammdaten!$G$4:$G$9,MATCH($A12,Stammdaten!$A$4:$A$9,0)),0)))) -> 5 | J12: =IF(AND($D12<>"",$I12<>""),COUNTIFS($D$2:$D12,"<>",$I$2:$I12,"<>"),"")
A13: E3 | B13: =IF($A13="","",IFERROR(INDEX(Stammdaten!$B$4:$B$9,MATCH($A13,Stammdaten!$A$4:$A$9,0)),"")) -> 46131 | C13: Türkontrolle | D13: Schuler Karl | E13: SV F'bach-Pf'kon | F13: x | H13: =IF($D13="","",IF($F13="",0,IF($G13<>"",$G13,IFERROR(INDEX(Stammdaten!$G$4:$G$9,MATCH($A13,Stammdaten!$A$4:$A$9,0)),0)))) -> 3 | J13: =IF(AND($D13<>"",$I13<>""),COUNTIFS($D$2:$D13,"<>",$I$2:$I13,"<>"),"")
... A98: E3 | B98: =IF($A98="","",IFERROR(INDEX(Stammdaten!$B$4:$B$9,MATCH($A98,Stammdaten!$A$4:$A$9,0)),"")) -> 46131 | C98: Warner | D98: Schuler Werner | E98: SV F'bach-Pf'kon | F98: OK | H98: =IF($D98="","",IF($F98="",0,IF($G98<>"",$G98,IFERROR(INDEX(Stammdaten!$G$4:$G$9,MATCH($A98,Stammdaten!$A$4:$A$9,0)),0)))) -> 3 | J98: =IF(AND($D98<>"",$I98<>""),COUNTIFS($D$2:$D98,"<>",$I$2:$I98,"<>"),"")
A99: E5 | B99: =IF($A99="","",IFERROR(INDEX(Stammdaten!$B$4:$B$9,MATCH($A99,Stammdaten!$A$4:$A$9,0)),"")) -> 45773 | C99: Warner | D99: Blättler Renata | E99: SV Wollerau | F99: x | H99: =IF($D99="","",IF($F99="",0,IF($G99<>"",$G99,IFERROR(INDEX(Stammdaten!$G$4:$G$9,MATCH($A99,Stammdaten!$A$4:$A$9,0)),0)))) -> 5 | I99: Nachtrag: Einsatz Samstag, 26.04.2025 vormittags – in der Liste 2026 nicht erfasst (in der Abrechnung 2025 ohne Stundenwert) | J99: =IF(AND($D99<>"",$I99<>""),COUNTIFS($D$2:$D99,"<>",$I$2:$I99,"<>"),"") -> 1
B100: =IF($A100="","",IFERROR(INDEX(Stammdaten!$B$4:$B$9,MATCH($A100,Stammdaten!$A$4:$A$9,0)),"")) | H100: =IF($D100="","",IF($F100="",0,IF($G100<>"",$G100,IFERROR(INDEX(Stammdaten!$G$4:$G$9,MATCH($A100,Stammdaten!$A$4:$A$9,0)),0)))) | J100: =IF(AND($D100<>"",$I100<>""),COUNTIFS($D$2:$D100,"<>",$I$2:$I100,"<>"),"")
B101: =IF($A101="","",IFERROR(INDEX(Stammdaten!$B$4:$B$9,MATCH($A101,Stammdaten!$A$4:$A$9,0)),"")) | H101: =IF($D101="","",IF($F101="",0,IF($G101<>"",$G101,IFERROR(INDEX(Stammdaten!$G$4:$G$9,MATCH($A101,Stammdaten!$A$4:$A$9,0)),0)))) | J101: =IF(AND($D101<>"",$I101<>""),COUNTIFS($D$2:$D101,"<>",$I$2:$I101,"<>"),"")
B102: =IF($A102="","",IFERROR(INDEX(Stammdaten!$B$4:$B$9,MATCH($A102,Stammdaten!$A$4:$A$9,0)),"")) | H102: =IF($D102="","",IF($F102="",0,IF($G102<>"",$G102,IFERROR(INDEX(Stammdaten!$G$4:$G$9,MATCH($A102,Stammdaten!$A$4:$A$9,0)),0)))) | J102: =IF(AND($D102<>"",$I102<>""),COUNTIFS($D$2:$D102,"<>",$I$2:$I102,"<>"),"")
B103: =IF($A103="","",IFERROR(INDEX(Stammdaten!$B$4:$B$9,MATCH($A103,Stammdaten!$A$4:$A$9,0)),"")) | H103: =IF($D103="","",IF($F103="",0,IF($G103<>"",$G103,IFERROR(INDEX(Stammdaten!$G$4:$G$9,MATCH($A103,Stammdaten!$A$4:$A$9,0)),0)))) | J103: =IF(AND($D103<>"",$I103<>""),COUNTIFS($D$2:$D103,"<>",$I$2:$I103,"<>"),"")
B104: =IF($A104="","",IFERROR(INDEX(Stammdaten!$B$4:$B$9,MATCH($A104,Stammdaten!$A$4:$A$9,0)),"")) | H104: =IF($D104="","",IF($F104="",0,IF($G104<>"",$G104,IFERROR(INDEX(Stammdaten!$G$4:$G$9,MATCH($A104,Stammdaten!$A$4:$A$9,0)),0)))) | J104: =IF(AND($D104<>"",$I104<>""),COUNTIFS($D$2:$D104,"<>",$I$2:$I104,"<>"),"")
B105: =IF($A105="","",IFERROR(INDEX(Stammdaten!$B$4:$B$9,MATCH($A105,Stammdaten!$A$4:$A$9,0)),"")) | H105: =IF($D105="","",IF($F105="",0,IF($G105<>"",$G105,IFERROR(INDEX(Stammdaten!$G$4:$G$9,MATCH($A105,Stammdaten!$A$4:$A$9,0)),0)))) | J105: =IF(AND($D105<>"",$I105<>""),COUNTIFS($D$2:$D105,"<>",$I$2:$I105,"<>"),"")
B106: =IF($A106="","",IFERROR(INDEX(Stammdaten!$B$4:$B$9,MATCH($A106,Stammdaten!$A$4:$A$9,0)),"")) | H106: =IF($D106="","",IF($F106="",0,IF($G106<>"",$G106,IFERROR(INDEX(Stammdaten!$G$4:$G$9,MATCH($A106,Stammdaten!$A$4:$A$9,0)),0)))) | J106: =IF(AND($D106<>"",$I106<>""),COUNTIFS($D$2:$D106,"<>",$I$2:$I106,"<>"),"")
B107: =IF($A107="","",IFERROR(INDEX(Stammdaten!$B$4:$B$9,MATCH($A107,Stammdaten!$A$4:$A$9,0)),"")) | H107: =IF($D107="","",IF($F107="",0,IF($G107<>"",$G107,IFERROR(INDEX(Stammdaten!$G$4:$G$9,MATCH($A107,Stammdaten!$A$4:$A$9,0)),0)))) | J107: =IF(AND($D107<>"",$I107<>""),COUNTIFS($D$2:$D107,"<>",$I$2:$I107,"<>"),"")
B108: =IF($A108="","",IFERROR(INDEX(Stammdaten!$B$4:$B$9,MATCH($A108,Stammdaten!$A$4:$A$9,0)),"")) | H108: =IF($D108="","",IF($F108="",0,IF($G108<>"",$G108,IFERROR(INDEX(Stammdaten!$G$4:$G$9,MATCH($A108,Stammdaten!$A$4:$A$9,0)),0)))) | J108: =IF(AND($D108<>"",$I108<>""),COUNTIFS($D$2:$D108,"<>",$I$2:$I108,"<>"),"")
B109: =IF($A109="","",IFERROR(INDEX(Stammdaten!$B$4:$B$9,MATCH($A109,Stammdaten!$A$4:$A$9,0)),"")) | H109: =IF($D109="","",IF($F109="",0,IF($G109<>"",$G109,IFERROR(INDEX(Stammdaten!$G$4:$G$9,MATCH($A109,Stammdaten!$A$4:$A$9,0)),0)))) | J109: =IF(AND($D109<>"",$I109<>""),COUNTIFS($D$2:$D109,"<>",$I$2:$I109,"<>"),"")
B110: =IF($A110="","",IFERROR(INDEX(Stammdaten!$B$4:$B$9,MATCH($A110,Stammdaten!$A$4:$A$9,0)),"")) | H110: =IF($D110="","",IF($F110="",0,IF($G110<>"",$G110,IFERROR(INDEX(Stammdaten!$G$4:$G$9,MATCH($A110,Stammdaten!$A$4:$A$9,0)),0)))) | J110: =IF(AND($D110<>"",$I110<>""),COUNTIFS($D$2:$D110,"<>",$I$2:$I110,"<>"),"")
B111: =IF($A111="","",IFERROR(INDEX(Stammdaten!$B$4:$B$9,MATCH($A111,Stammdaten!$A$4:$A$9,0)),"")) | H111: =IF($D111="","",IF($F111="",0,IF($G111<>"",$G111,IFERROR(INDEX(Stammdaten!$G$4:$G$9,MATCH($A111,Stammdaten!$A$4:$A$9,0)),0)))) | J111: =IF(AND($D111<>"",$I111<>""),COUNTIFS($D$2:$D111,"<>",$I$2:$I111,"<>"),"")
... B200: =IF($A200="","",IFERROR(INDEX(Stammdaten!$B$4:$B$9,MATCH($A200,Stammdaten!$A$4:$A$9,0)),"")) | H200: =IF($D200="","",IF($F200="",0,IF($G200<>"",$G200,IFERROR(INDEX(Stammdaten!$G$4:$G$9,MATCH($A200,Stammdaten!$A$4:$A$9,0)),0)))) | J200: =IF(AND($D200<>"",$I200<>""),COUNTIFS($D$2:$D200,"<>",$I$2:$I200,"<>"),"")

Sheet Stammdaten
A1: Stammdaten
A2: Gelbe Zellen sind Eingabefelder. Änderungen wirken sich sofort auf alle Auswertungen aus.
A3: Einsatz-ID | B3: Datum | C3: Zeit | D3: Treffpunkt | E3: Dauer (h) | F3: Zuschlag Treffpunkt (h) | G3: Stunden pro Einsatz | H3: Bemerkung
A4: E1 | B4: 46130 | C4: 08.00 – 12.00 Uhr | D4: 07.30 Uhr (Büro 07.15) | E4: 5 | F4: 0 | G4: =IF($A4="","",N($E4)+N($F4)) -> 5 | H4: 1. Samstag, Vormittag · Pauschale 5.00 gemäss Abrechnung 2025
A5: E2 | B5: 46130 | C5: 13.30 – 17.00 Uhr | D5: 13.15 Uhr (Büro 13.00) | E5: 5 | F5: 0 | G5: =IF($A5="","",N($E5)+N($F5)) -> 5 | H5: 1. Samstag, Nachmittag · Pauschale 5.00 gemäss Abrechnung 2025
A6: E3 | B6: 46131 | C6: 09.30 – 11.30 Uhr | D6: 09.00 Uhr (Büro 08.45) | E6: 3 | F6: 0 | G6: =IF($A6="","",N($E6)+N($F6)) -> 3 | H6: Sonntag · Pauschale 3.00 gemäss Abrechnung 2025
A7: E4 | B7: 46137 | C7: 08.00 – 12.00 Uhr | D7: 07.30 Uhr (Büro 07.15) | E7: 5 | F7: 0 | G7: =IF($A7="","",N($E7)+N($F7)) -> 5 | H7: 2. Samstag · Pauschale 5.00 gemäss Abrechnung 2025
A8: E5 | B8: 45773 | C8: vormittags | E8: 5 | F8: 0 | G8: =IF($A8="","",N($E8)+N($F8)) -> 5 | H8: NACHTRAG aus 2025 – Samstagvormittag, Pauschale 5.00 gemäss Abrechnung 2025
G9: =IF($A9="","",N($E9)+N($F9)) | H9: freie Zeile für einen zusätzlichen Einsatz
A11: Hinweis: «Dauer» = Pauschale pro Helfereinsatz (5.00 Samstag / 3.00 Sonntag, wie in der Abrechnung 2025). Über «Zuschlag Treffpunkt» lässt sich bei Bedarf zusätzlich aufrechnen.
A12: Vereine
A13: Verein | B13: Bemerkung
A14: SV F'bach-Pf'kon
A15: MSV Wilen
A16: SV Wollerau
B17: freie Zeile für einen zusätzlichen Verein
B18: freie Zeile für einen zusätzlichen Verein
B19: freie Zeile für einen zusätzlichen Verein

Sheet Pro Person
A1: Name / Vorname | B1: Verein | C1: Anzahl Einsätze | D1: Helferstunden
A2: Flühler Beat | B2: SV F'bach-Pf'kon | C2: =IF($A2="","",COUNTIFS(Zuteilungen!$D$2:$D$200,$A2,Zuteilungen!$F$2:$F$200,"x")+IF(Uebersicht!$B$5="JA",COUNTIFS(Zuteilungen!$D$2:$D$200,$A2,Zuteilungen!$F$2:$F$200,"OK"),0)) -> 1 | D2: =IF($A2="","",SUMIFS(Zuteilungen!$H$2:$H$200,Zuteilungen!$D$2:$D$200,$A2,Zuteilungen!$F$2:$F$200,"x")+IF(Uebersicht!$B$5="JA",SUMIFS(Zuteilungen!$H$2:$H$200,Zuteilungen!$D$2:$D$200,$A2,Zuteilungen!$F$2:$F$200,"OK"),0)) -> 5
A3: Flühler Georges | B3: SV F'bach-Pf'kon | C3: =IF($A3="","",COUNTIFS(Zuteilungen!$D$2:$D$200,$A3,Zuteilungen!$F$2:$F$200,"x")+IF(Uebersicht!$B$5="JA",COUNTIFS(Zuteilungen!$D$2:$D$200,$A3,Zuteilungen!$F$2:$F$200,"OK"),0)) -> 4 | D3: =IF($A3="","",SUMIFS(Zuteilungen!$H$2:$H$200,Zuteilungen!$D$2:$D$200,$A3,Zuteilungen!$F$2:$F$200,"x")+IF(Uebersicht!$B$5="JA",SUMIFS(Zuteilungen!$H$2:$H$200,Zuteilungen!$D$2:$D$200,$A3,Zuteilungen!$F$2:$F$200,"OK"),0)) -> 18
A4: Graden Rolf | B4: SV F'bach-Pf'kon | C4: =IF($A4="","",COUNTIFS(Zuteilungen!$D$2:$D$200,$A4,Zuteilungen!$F$2:$F$200,"x")+IF(Uebersicht!$B$5="JA",COUNTIFS(Zuteilungen!$D$2:$D$200,$A4,Zuteilungen!$F$2:$F$200,"OK"),0)) -> 2 | D4: =IF($A4="","",SUMIFS(Zuteilungen!$H$2:$H$200,Zuteilungen!$D$2:$D$200,$A4,Zuteilungen!$F$2:$F$200,"x")+IF(Uebersicht!$B$5="JA",SUMIFS(Zuteilungen!$H$2:$H$200,Zuteilungen!$D$2:$D$200,$A4,Zuteilungen!$F$2:$F$200,"OK"),0)) -> 10
A5: Jehli Christian | B5: SV F'bach-Pf'kon | C5: =IF($A5="","",COUNTIFS(Zuteilungen!$D$2:$D$200,$A5,Zuteilungen!$F$2:$F$200,"x")+IF(Uebersicht!$B$5="JA",COUNTIFS(Zuteilungen!$D$2:$D$200,$A5,Zuteilungen!$F$2:$F$200,"OK"),0)) -> 3 | D5: =IF($A5="","",SUMIFS(Zuteilungen!$H$2:$H$200,Zuteilungen!$D$2:$D$200,$A5,Zuteilungen!$F$2:$F$200,"x")+IF(Uebersicht!$B$5="JA",SUMIFS(Zuteilungen!$H$2:$H$200,Zuteilungen!$D$2:$D$200,$A5,Zuteilungen!$F$2:$F$200,"OK"),0)) -> 15
A6: Lanelli Philipp | B6: SV F'bach-Pf'kon | C6: =IF($A6="","",COUNTIFS(Zuteilungen!$D$2:$D$200,$A6,Zuteilungen!$F$2:$F$200,"x")+IF(Uebersicht!$B$5="JA",COUNTIFS(Zuteilungen!$D$2:$D$200,$A6,Zuteilungen!$F$2:$F$200,"OK"),0)) -> 0 | D6: =IF($A6="","",SUMIFS(Zuteilungen!$H$2:$H$200,Zuteilungen!$D$2:$D$200,$A6,Zuteilungen!$F$2:$F$200,"x")+IF(Uebersicht!$B$5="JA",SUMIFS(Zuteilungen!$H$2:$H$200,Zuteilungen!$D$2:$D$200,$A6,Zuteilungen!$F$2:$F$200,"OK"),0)) -> 0
A7: Odermatt Marcel | B7: SV F'bach-Pf'kon | C7: =IF($A7="","",COUNTIFS(Zuteilungen!$D$2:$D$200,$A7,Zuteilungen!$F$2:$F$200,"x")+IF(Uebersicht!$B$5="JA",COUNTIFS(Zuteilungen!$D$2:$D$200,$A7,Zuteilungen!$F$2:$F$200,"OK"),0)) -> 2 | D7: =IF($A7="","",SUMIFS(Zuteilungen!$H$2:$H$200,Zuteilungen!$D$2:$D$200,$A7,Zuteilungen!$F$2:$F$200,"x")+IF(Uebersicht!$B$5="JA",SUMIFS(Zuteilungen!$H$2:$H$200,Zuteilungen!$D$2:$D$200,$A7,Zuteilungen!$F$2:$F$200,"OK"),0)) -> 10
A8: Pargätzi Bruna | B8: SV F'bach-Pf'kon | C8: =IF($A8="","",COUNTIFS(Zuteilungen!$D$2:$D$200,$A8,Zuteilungen!$F$2:$F$200,"x")+IF(Uebersicht!$B$5="JA",COUNTIFS(Zuteilungen!$D$2:$D$200,$A8,Zuteilungen!$F$2:$F$200,"OK"),0)) -> 0 | D8: =IF($A8="","",SUMIFS(Zuteilungen!$H$2:$H$200,Zuteilungen!$D$2:$D$200,$A8,Zuteilungen!$F$2:$F$200,"x")+IF(Uebersicht!$B$5="JA",SUMIFS(Zuteilungen!$H$2:$H$200,Zuteilungen!$D$2:$D$200,$A8,Zuteilungen!$F$2:$F$200,"OK"),0)) -> 0
A9: Schuler Karl | B9: SV F'bach-Pf'kon | C9: =IF($A9="","",COUNTIFS(Zuteilungen!$D$2:$D$200,$A9,Zuteilungen!$F$2:$F$200,"x")+IF(Uebersicht!$B$5="JA",COUNTIFS(Zuteilungen!$D$2:$D$200,$A9,Zuteilungen!$F$2:$F$200,"OK"),0)) -> 3 | D9: =IF($A9="","",SUMIFS(Zuteilungen!$H$2:$H$200,Zuteilungen!$D$2:$D$200,$A9,Zuteilungen!$F$2:$F$200,"x")+IF(Uebersicht!$B$5="JA",SUMIFS(Zuteilungen!$H$2:$H$200,Zuteilungen!$D$2:$D$200,$A9,Zuteilungen!$F$2:$F$200,"OK"),0)) -> 13
A10: Schuler Werner | B10: SV F'bach-Pf'kon | C10: =IF($A10="","",COUNTIFS(Zuteilungen!$D$2:$D$200,$A10,Zuteilungen!$F$2:$F$200,"x")+IF(Uebersicht!$B$5="JA",COUNTIFS(Zuteilungen!$D$2:$D$200,$A10,Zuteilungen!$F$2:$F$200,"OK"),0)) -> 0 | D10: =IF($A10="","",SUMIFS(Zuteilungen!$H$2:$H$200,Zuteilungen!$D$2:$D$200,$A10,Zuteilungen!$F$2:$F$200,"x")+IF(Uebersicht!$B$5="JA",SUMIFS(Zuteilungen!$H$2:$H$200,Zuteilungen!$D$2:$D$200,$A10,Zuteilungen!$F$2:$F$200,"OK"),0)) -> 0
A11: Steiner Alfred | B11: SV F'bach-Pf'kon | C11: =IF($A11="","",COUNTIFS(Zuteilungen!$D$2:$D$200,$A11,Zuteilungen!$F$2:$F$200,"x")+IF(Uebersicht!$B$5="JA",COUNTIFS(Zuteilungen!$D$2:$D$200,$A11,Zuteilungen!$F$2:$F$200,"OK"),0)) -> 3 | D11: =IF($A11="","",SUMIFS(Zuteilungen!$H$2:$H$200,Zuteilungen!$D$2:$D$200,$A11,Zuteilungen!$F$2:$F$200,"x")+IF(Uebersicht!$B$5="JA",SUMIFS(Zuteilungen!$H$2:$H$200,Zuteilungen!$D$2:$D$200,$A11,Zuteilungen!$F$2:$F$200,"OK"),0)) -> 13
A12: Strickler Julius | B12: SV F'bach-Pf'kon | C12: =IF($A12="","",COUNTIFS(Zuteilungen!$D$2:$D$200,$A12,Zuteilungen!$F$2:$F$200,"x")+IF(Uebersicht!$B$5="JA",COUNTIFS(Zuteilungen!$D$2:$D$200,$A12,Zuteilungen!$F$2:$F$200,"OK"),0)) -> 2 | D12: =IF($A12="","",SUMIFS(Zuteilungen!$H$2:$H$200,Zuteilungen!$D$2:$D$200,$A12,Zuteilungen!$F$2:$F$200,"x")+IF(Uebersicht!$B$5="JA",SUMIFS(Zuteilungen!$H$2:$H$200,Zuteilungen!$D$2:$D$200,$A12,Zuteilungen!$F$2:$F$200,"OK"),0)) -> 8
A13: Wyler Hanspeter | B13: SV F'bach-Pf'kon | C13: =IF($A13="","",COUNTIFS(Zuteilungen!$D$2:$D$200,$A13,Zuteilungen!$F$2:$F$200,"x")+IF(Uebersicht!$B$5="JA",COUNTIFS(Zuteilungen!$D$2:$D$200,$A13,Zuteilungen!$F$2:$F$200,"OK"),0)) -> 3 | D13: =IF($A13="","",SUMIFS(Zuteilungen!$H$2:$H$200,Zuteilungen!$D$2:$D$200,$A13,Zuteilungen!$F$2:$F$200,"x")+IF(Uebersicht!$B$5="JA",SUMIFS(Zuteilungen!$H$2:$H$200,Zuteilungen!$D$2:$D$200,$A13,Zuteilungen!$F$2:$F$200,"OK"),0)) -> 13
... A46: Steinegger Josef | B46: SV Wollerau | C46: =IF($A46="","",COUNTIFS(Zuteilungen!$D$2:$D$200,$A46,Zuteilungen!$F$2:$F$200,"x")+IF(Uebersicht!$B$5="JA",COUNTIFS(Zuteilungen!$D$2:$D$200,$A46,Zuteilungen!$F$2:$F$200,"OK"),0)) -> 2 | D46: =IF($A46="","",SUMIFS(Zuteilungen!$H$2:$H$200,Zuteilungen!$D$2:$D$200,$A46,Zuteilungen!$F$2:$F$200,"x")+IF(Uebersicht!$B$5="JA",SUMIFS(Zuteilungen!$H$2:$H$200,Zuteilungen!$D$2:$D$200,$A46,Zuteilungen!$F$2:$F$200,"OK"),0)) -> 8
C47: =IF($A47="","",COUNTIFS(Zuteilungen!$D$2:$D$200,$A47,Zuteilungen!$F$2:$F$200,"x")+IF(Uebersicht!$B$5="JA",COUNTIFS(Zuteilungen!$D$2:$D$200,$A47,Zuteilungen!$F$2:$F$200,"OK"),0)) | D47: =IF($A47="","",SUMIFS(Zuteilungen!$H$2:$H$200,Zuteilungen!$D$2:$D$200,$A47,Zuteilungen!$F$2:$F$200,"x")+IF(Uebersicht!$B$5="JA",SUMIFS(Zuteilungen!$H$2:$H$200,Zuteilungen!$D$2:$D$200,$A47,Zuteilungen!$F$2:$F$200,"OK"),0))
C48: =IF($A48="","",COUNTIFS(Zuteilungen!$D$2:$D$200,$A48,Zuteilungen!$F$2:$F$200,"x")+IF(Uebersicht!$B$5="JA",COUNTIFS(Zuteilungen!$D$2:$D$200,$A48,Zuteilungen!$F$2:$F$200,"OK"),0)) | D48: =IF($A48="","",SUMIFS(Zuteilungen!$H$2:$H$200,Zuteilungen!$D$2:$D$200,$A48,Zuteilungen!$F$2:$F$200,"x")+IF(Uebersicht!$B$5="JA",SUMIFS(Zuteilungen!$H$2:$H$200,Zuteilungen!$D$2:$D$200,$A48,Zuteilungen!$F$2:$F$200,"OK"),0))
C49: =IF($A49="","",COUNTIFS(Zuteilungen!$D$2:$D$200,$A49,Zuteilungen!$F$2:$F$200,"x")+IF(Uebersicht!$B$5="JA",COUNTIFS(Zuteilungen!$D$2:$D$200,$A49,Zuteilungen!$F$2:$F$200,"OK"),0)) | D49: =IF($A49="","",SUMIFS(Zuteilungen!$H$2:$H$200,Zuteilungen!$D$2:$D$200,$A49,Zuteilungen!$F$2:$F$200,"x")+IF(Uebersicht!$B$5="JA",SUMIFS(Zuteilungen!$H$2:$H$200,Zuteilungen!$D$2:$D$200,$A49,Zuteilungen!$F$2:$F$200,"OK"),0))
C50: =IF($A50="","",COUNTIFS(Zuteilungen!$D$2:$D$200,$A50,Zuteilungen!$F$2:$F$200,"x")+IF(Uebersicht!$B$5="JA",COUNTIFS(Zuteilungen!$D$2:$D$200,$A50,Zuteilungen!$F$2:$F$200,"OK"),0)) | D50: =IF($A50="","",SUMIFS(Zuteilungen!$H$2:$H$200,Zuteilungen!$D$2:$D$200,$A50,Zuteilungen!$F$2:$F$200,"x")+IF(Uebersicht!$B$5="JA",SUMIFS(Zuteilungen!$H$2:$H$200,Zuteilungen!$D$2:$D$200,$A50,Zuteilungen!$F$2:$F$200,"OK"),0))
C51: =IF($A51="","",COUNTIFS(Zuteilungen!$D$2:$D$200,$A51,Zuteilungen!$F$2:$F$200,"x")+IF(Uebersicht!$B$5="JA",COUNTIFS(Zuteilungen!$D$2:$D$200,$A51,Zuteilungen!$F$2:$F$200,"OK"),0)) | D51: =IF($A51="","",SUMIFS(Zuteilungen!$H$2:$H$200,Zuteilungen!$D$2:$D$200,$A51,Zuteilungen!$F$2:$F$200,"x")+IF(Uebersicht!$B$5="JA",SUMIFS(Zuteilungen!$H$2:$H$200,Zuteilungen!$D$2:$D$200,$A51,Zuteilungen!$F$2:$F$200,"OK"),0))
C52: =IF($A52="","",COUNTIFS(Zuteilungen!$D$2:$D$200,$A52,Zuteilungen!$F$2:$F$200,"x")+IF(Uebersicht!$B$5="JA",COUNTIFS(Zuteilungen!$D$2:$D$200,$A52,Zuteilungen!$F$2:$F$200,"OK"),0)) | D52: =IF($A52="","",SUMIFS(Zuteilungen!$H$2:$H$200,Zuteilungen!$D$2:$D$200,$A52,Zuteilungen!$F$2:$F$200,"x")+IF(Uebersicht!$B$5="JA",SUMIFS(Zuteilungen!$H$2:$H$200,Zuteilungen!$D$2:$D$200,$A52,Zuteilungen!$F$2:$F$200,"OK"),0))
C53: =IF($A53="","",COUNTIFS(Zuteilungen!$D$2:$D$200,$A53,Zuteilungen!$F$2:$F$200,"x")+IF(Uebersicht!$B$5="JA",COUNTIFS(Zuteilungen!$D$2:$D$200,$A53,Zuteilungen!$F$2:$F$200,"OK"),0)) | D53: =IF($A53="","",SUMIFS(Zuteilungen!$H$2:$H$200,Zuteilungen!$D$2:$D$200,$A53,Zuteilungen!$F$2:$F$200,"x")+IF(Uebersicht!$B$5="JA",SUMIFS(Zuteilungen!$H$2:$H$200,Zuteilungen!$D$2:$D$200,$A53,Zuteilungen!$F$2:$F$200,"OK"),0))
C54: =IF($A54="","",COUNTIFS(Zuteilungen!$D$2:$D$200,$A54,Zuteilungen!$F$2:$F$200,"x")+IF(Uebersicht!$B$5="JA",COUNTIFS(Zuteilungen!$D$2:$D$200,$A54,Zuteilungen!$F$2:$F$200,"OK"),0)) | D54: =IF($A54="","",SUMIFS(Zuteilungen!$H$2:$H$200,Zuteilungen!$D$2:$D$200,$A54,Zuteilungen!$F$2:$F$200,"x")+IF(Uebersicht!$B$5="JA",SUMIFS(Zuteilungen!$H$2:$H$200,Zuteilungen!$D$2:$D$200,$A54,Zuteilungen!$F$2:$F$200,"OK"),0))
C55: =IF($A55="","",COUNTIFS(Zuteilungen!$D$2:$D$200,$A55,Zuteilungen!$F$2:$F$200,"x")+IF(Uebersicht!$B$5="JA",COUNTIFS(Zuteilungen!$D$2:$D$200,$A55,Zuteilungen!$F$2:$F$200,"OK"),0)) | D55: =IF($A55="","",SUMIFS(Zuteilungen!$H$2:$H$200,Zuteilungen!$D$2:$D$200,$A55,Zuteilungen!$F$2:$F$200,"x")+IF(Uebersicht!$B$5="JA",SUMIFS(Zuteilungen!$H$2:$H$200,Zuteilungen!$D$2:$D$200,$A55,Zuteilungen!$F$2:$F$200,"OK"),0))
C56: =IF($A56="","",COUNTIFS(Zuteilungen!$D$2:$D$200,$A56,Zuteilungen!$F$2:$F$200,"x")+IF(Uebersicht!$B$5="JA",COUNTIFS(Zuteilungen!$D$2:$D$200,$A56,Zuteilungen!$F$2:$F$200,"OK"),0)) | D56: =IF($A56="","",SUMIFS(Zuteilungen!$H$2:$H$200,Zuteilungen!$D$2:$D$200,$A56,Zuteilungen!$F$2:$F$200,"x")+IF(Uebersicht!$B$5="JA",SUMIFS(Zuteilungen!$H$2:$H$200,Zuteilungen!$D$2:$D$200,$A56,Zuteilungen!$F$2:$F$200,"OK"),0))
C57: =IF($A57="","",COUNTIFS(Zuteilungen!$D$2:$D$200,$A57,Zuteilungen!$F$2:$F$200,"x")+IF(Uebersicht!$B$5="JA",COUNTIFS(Zuteilungen!$D$2:$D$200,$A57,Zuteilungen!$F$2:$F$200,"OK"),0)) | D57: =IF($A57="","",SUMIFS(Zuteilungen!$H$2:$H$200,Zuteilungen!$D$2:$D$200,$A57,Zuteilungen!$F$2:$F$200,"x")+IF(Uebersicht!$B$5="JA",SUMIFS(Zuteilungen!$H$2:$H$200,Zuteilungen!$D$2:$D$200,$A57,Zuteilungen!$F$2:$F$200,"OK"),0))
C58: =IF($A58="","",COUNTIFS(Zuteilungen!$D$2:$D$200,$A58,Zuteilungen!$F$2:$F$200,"x")+IF(Uebersicht!$B$5="JA",COUNTIFS(Zuteilungen!$D$2:$D$200,$A58,Zuteilungen!$F$2:$F$200,"OK"),0)) | D58: =IF($A58="","",SUMIFS(Zuteilungen!$H$2:$H$200,Zuteilungen!$D$2:$D$200,$A58,Zuteilungen!$F$2:$F$200,"x")+IF(Uebersicht!$B$5="JA",SUMIFS(Zuteilungen!$H$2:$H$200,Zuteilungen!$D$2:$D$200,$A58,Zuteilungen!$F$2:$F$200,"OK"),0))
... C71: =IF($A71="","",COUNTIFS(Zuteilungen!$D$2:$D$200,$A71,Zuteilungen!$F$2:$F$200,"x")+IF(Uebersicht!$B$5="JA",COUNTIFS(Zuteilungen!$D$2:$D$200,$A71,Zuteilungen!$F$2:$F$200,"OK"),0)) | D71: =IF($A71="","",SUMIFS(Zuteilungen!$H$2:$H$200,Zuteilungen!$D$2:$D$200,$A71,Zuteilungen!$F$2:$F$200,"x")+IF(Uebersicht!$B$5="JA",SUMIFS(Zuteilungen!$H$2:$H$200,Zuteilungen!$D$2:$D$200,$A71,Zuteilungen!$F$2:$F$200,"OK"),0))

Sheet Vor- und Nacharbeiten
A1: Diverse Vor- & Nacharbeiten
A2: Arbeiten ausserhalb der Einsatzliste. Alle gelben Felder sind Eingabefelder; die Stunden fliessen automatisch in die Gesamtabrechnung im Blatt «Uebersicht».
A4: Tätigkeit | B4: Name / Vorname | C4: Verein | D4: Stunden | E4: Status | F4: Bemerkung / Vorjahr 2025
A5: Festführer zusammenstellen | B5: Schuler Werner | C5: SV F'bach-Pf'kon | D5: 0 | E5: x | F5: 2025: Schuler Werner
A6: Festführer Layout / PDF druckfertig | B6: Pargätzi Bruna | C6: SV Wollerau | D6: 0 | E6: x | F6: 2025: Pargätzi Bruna
A7: Festführer Layout / PDF druckfertig | B7: Bürgi Adrian | C7: SV Wollerau | D7: 10 | E7: x | F7: 2025: Bürgi Adrian
A8: Munition bereitstellen | B8: Steinegger Josef | C8: SV Wollerau | D8: 1 | E8: x | F8: 2025: Steinegger Josef
A9: Büro einrichten / EDV / Definition Fest | B9: Linggi Renato | C9: MSV Wilen | D9: 0 | E9: x | F9: 2025: Linggi Renato
A10: Büro einrichten / EDV / Definition Fest | B10: Cavelti Roger | C10: MSV Wilen | D10: 1 | E10: x | F10: 2025: Cavelti Roger
A11: Büro einrichten / EDV / Definition Fest | E11: x | F11: 2025: Schuler Werner
A12: Verpflegung | B12: Flühler Georges | C12: SV F'bach-Pf'kon | D12: 4 | E12: x | F12: 2025: Flühler Georges
A13: Verpflegung | B13: Wyler Hanspeter | C13: SV F'bach-Pf'kon | D13: 4 | E13: x | F13: 2025: Wyler Hanspeter
A14: Vorschiessen (2x Mittwochabend) | B14: Schuler Werner (Büro) | C14: SV F'bach-Pf'kon | D14: 0 | E14: x | F14: 2025: Schuler Werner (Büro)
A15: Vorschiessen (2x Mittwochabend) | B15: Linggi Res (SM) | C15: MSV Wilen | D15: 0 | E15: x | F15: 2025: Linggi Res (SM)
A16: Vorschiessen (2x Mittwochabend) | B16: Cavelti Roger | C16: MSV Wilen | D16: 2 | E16: x | F16: 2025: Linggi Renato
A17: Aufräumen Reklamen | B17: Schuler Werner | C17: SV F'bach-Pf'kon | D17: 0 | E17: x | F17: 2025: Schuler Werner
A18: Aufräumen Büro / EDV / Munition | B18: Linggi Renato | C18: MSV Wilen | D18: 0 | E18: x | F18: 2025: Linggi Renato
A19: Aufräumen Büro / EDV / Munition | B19: Cavelti Roger | C19: SV Wollerau | D19: 1 | E19: x | F19: 2025: Steinegger Josef
A20: OK – Präsident | B20: Linggi Renato | C20: MSV Wilen | D20: 50 | E20: x | F20: 2025: Linggi Renato
A21: OK – Werbung / Sponsoring | B21: Schuler Werner | C21: SV F'bach-Pf'kon | D21: 50 | E21: x | F21: 2025: Schuler Werner
A22: OK – Kasse | B22: Lanelli Philipp | C22: SV F'bach-Pf'kon | D22: 50 | E22: x | F22: 2025: Lanelli Philipp
A23: OK – Schützenmeister | B23: Linggi Andreas | C23: MSV Wilen | D23: 50 | E23: x | F23: 2025: Linggi Res
A24: OK – Anmeldung / Internet | B24: Pargätzi Bruna | C24: SV Wollerau | D24: 50 | E24: x | F24: 2025: Pargätzi Bruna
A66: Total pro Verein | D66: Stunden «x» | E66: Stunden «OK»
A67: =IF(Stammdaten!$A$14="","",Stammdaten!$A$14) -> SV F'bach-Pf'kon | D67: =SUMIFS($D$5:$D$64,$C$5:$C$64,$A67,$E$5:$E$64,"x") -> 108 | E67: =SUMIFS($D$5:$D$64,$C$5:$C$64,$A67,$E$5:$E$64,"OK") -> 0
A68: =IF(Stammdaten!$A$15="","",Stammdaten!$A$15) -> MSV Wilen | D68: =SUMIFS($D$5:$D$64,$C$5:$C$64,$A68,$E$5:$E$64,"x") -> 103 | E68: =SUMIFS($D$5:$D$64,$C$5:$C$64,$A68,$E$5:$E$64,"OK") -> 0
A69: =IF(Stammdaten!$A$16="","",Stammdaten!$A$16) -> SV Wollerau | D69: =SUMIFS($D$5:$D$64,$C$5:$C$64,$A69,$E$5:$E$64,"x") -> 62 | E69: =SUMIFS($D$5:$D$64,$C$5:$C$64,$A69,$E$5:$E$64,"OK") -> 0
A71: Hinweis: Die Tätigkeiten stammen aus der Abrechnung 2025 und sind als Vorlage eingetragen – Zeilen frei änder-, lösch- und ergänzbar.
A72: Status «x» zählt dem Verein an, «OK» nur wenn der Schalter in der Übersicht auf JA steht. In der Abrechnung 2025 wurden OK-Stunden separat ausgewiesen.

Sheet Korrekturen
A1: Korrekturen & Kommentare
A2: Listet automatisch jede Zeile aus dem Blatt «Zuteilungen», in der ein Kommentar erfasst ist – manuelle Nachträge, Korrekturen und Anmerkungen. Kommentiert wird immer im Blatt «Zuteilungen», Spalte I.
A4: Nr. | B4: Einsatz | C4: Datum | D4: Funktion | E4: Name / Vorname | F4: Verein | G4: Status | H4: Stunden | I4: Kommentar
A5: =IFERROR(IF(MATCH(1,Zuteilungen!$J$2:$J$200,0)>0,1,""),"") -> 1 | B5: =IFERROR(IF(INDEX(Zuteilungen!$A$2:$A$200,MATCH(1,Zuteilungen!$J$2:$J$200,0))="","",INDEX(Zuteilungen!$A$2:$A$200,MATCH(1,Zuteilungen!$J$2:$J$200,0))),"") -> E5 | C5: =IFERROR(IF(INDEX(Zuteilungen!$B$2:$B$200,MATCH(1,Zuteilungen!$J$2:$J$200,0))="","",INDEX(Zuteilungen!$B$2:$B$200,MATCH(1,Zuteilungen!$J$2:$J$200,0))),"") -> 45773 | D5: =IFERROR(IF(INDEX(Zuteilungen!$C$2:$C$200,MATCH(1,Zuteilungen!$J$2:$J$200,0))="","",INDEX(Zuteilungen!$C$2:$C$200,MATCH(1,Zuteilungen!$J$2:$J$200,0))),"") -> Warner | E5: =IFERROR(IF(INDEX(Zuteilungen!$D$2:$D$200,MATCH(1,Zuteilungen!$J$2:$J$200,0))="","",INDEX(Zuteilungen!$D$2:$D$200,MATCH(1,Zuteilungen!$J$2:$J$200,0))),"") -> Blättler Renata | F5: =IFERROR(IF(INDEX(Zuteilungen!$E$2:$E$200,MATCH(1,Zuteilungen!$J$2:$J$200,0))="","",INDEX(Zuteilungen!$E$2:$E$200,MATCH(1,Zuteilungen!$J$2:$J$200,0))),"") -> SV Wollerau | G5: =IFERROR(IF(INDEX(Zuteilungen!$F$2:$F$200,MATCH(1,Zuteilungen!$J$2:$J$200,0))="","",INDEX(Zuteilungen!$F$2:$F$200,MATCH(1,Zuteilungen!$J$2:$J$200,0))),"") -> x | H5: =IFERROR(IF(INDEX(Zuteilungen!$H$2:$H$200,MATCH(1,Zuteilungen!$J$2:$J$200,0))="","",INDEX(Zuteilungen!$H$2:$H$200,MATCH(1,Zuteilungen!$J$2:$J$200,0))),"") -> 5 | I5: =IFERROR(IF(INDEX(Zuteilungen!$I$2:$I$200,MATCH(1,Zuteilungen!$J$2:$J$200,0))="","",INDEX(Zuteilungen!$I$2:$I$200,MATCH(1,Zuteilungen!$J$2:$J$200,0))),"") -> Nachtrag: Einsatz Samstag, 26.04.2025 vormittags – in der Liste 2026 nicht erfasst (in der Abrechnung 2025 ohne Stundenwert)
A6: =IFERROR(IF(MATCH(2,Zuteilungen!$J$2:$J$200,0)>0,2,""),"") | B6: =IFERROR(IF(INDEX(Zuteilungen!$A$2:$A$200,MATCH(2,Zuteilungen!$J$2:$J$200,0))="","",INDEX(Zuteilungen!$A$2:$A$200,MATCH(2,Zuteilungen!$J$2:$J$200,0))),"") | C6: =IFERROR(IF(INDEX(Zuteilungen!$B$2:$B$200,MATCH(2,Zuteilungen!$J$2:$J$200,0))="","",INDEX(Zuteilungen!$B$2:$B$200,MATCH(2,Zuteilungen!$J$2:$J$200,0))),"") | D6: =IFERROR(IF(INDEX(Zuteilungen!$C$2:$C$200,MATCH(2,Zuteilungen!$J$2:$J$200,0))="","",INDEX(Zuteilungen!$C$2:$C$200,MATCH(2,Zuteilungen!$J$2:$J$200,0))),"") | E6: =IFERROR(IF(INDEX(Zuteilungen!$D$2:$D$200,MATCH(2,Zuteilungen!$J$2:$J$200,0))="","",INDEX(Zuteilungen!$D$2:$D$200,MATCH(2,Zuteilungen!$J$2:$J$200,0))),"") | F6: =IFERROR(IF(INDEX(Zuteilungen!$E$2:$E$200,MATCH(2,Zuteilungen!$J$2:$J$200,0))="","",INDEX(Zuteilungen!$E$2:$E$200,MATCH(2,Zuteilungen!$J$2:$J$200,0))),"") | G6: =IFERROR(IF(INDEX(Zuteilungen!$F$2:$F$200,MATCH(2,Zuteilungen!$J$2:$J$200,0))="","",INDEX(Zuteilungen!$F$2:$F$200,MATCH(2,Zuteilungen!$J$2:$J$200,0))),"") | H6: =IFERROR(IF(INDEX(Zuteilungen!$H$2:$H$200,MATCH(2,Zuteilungen!$J$2:$J$200,0))="","",INDEX(Zuteilungen!$H$2:$H$200,MATCH(2,Zuteilungen!$J$2:$J$200,0))),"") | I6: =IFERROR(IF(INDEX(Zuteilungen!$I$2:$I$200,MATCH(2,Zuteilungen!$J$2:$J$200,0))="","",INDEX(Zuteilungen!$I$2:$I$200,MATCH(2,Zuteilungen!$J$2:$J$200,0))),"")
A7: =IFERROR(IF(MATCH(3,Zuteilungen!$J$2:$J$200,0)>0,3,""),"") | B7: =IFERROR(IF(INDEX(Zuteilungen!$A$2:$A$200,MATCH(3,Zuteilungen!$J$2:$J$200,0))="","",INDEX(Zuteilungen!$A$2:$A$200,MATCH(3,Zuteilungen!$J$2:$J$200,0))),"") | C7: =IFERROR(IF(INDEX(Zuteilungen!$B$2:$B$200,MATCH(3,Zuteilungen!$J$2:$J$200,0))="","",INDEX(Zuteilungen!$B$2:$B$200,MATCH(3,Zuteilungen!$J$2:$J$200,0))),"") | D7: =IFERROR(IF(INDEX(Zuteilungen!$C$2:$C$200,MATCH(3,Zuteilungen!$J$2:$J$200,0))="","",INDEX(Zuteilungen!$C$2:$C$200,MATCH(3,Zuteilungen!$J$2:$J$200,0))),"") | E7: =IFERROR(IF(INDEX(Zuteilungen!$D$2:$D$200,MATCH(3,Zuteilungen!$J$2:$J$200,0))="","",INDEX(Zuteilungen!$D$2:$D$200,MATCH(3,Zuteilungen!$J$2:$J$200,0))),"") | F7: =IFERROR(IF(INDEX(Zuteilungen!$E$2:$E$200,MATCH(3,Zuteilungen!$J$2:$J$200,0))="","",INDEX(Zuteilungen!$E$2:$E$200,MATCH(3,Zuteilungen!$J$2:$J$200,0))),"") | G7: =IFERROR(IF(INDEX(Zuteilungen!$F$2:$F$200,MATCH(3,Zuteilungen!$J$2:$J$200,0))="","",INDEX(Zuteilungen!$F$2:$F$200,MATCH(3,Zuteilungen!$J$2:$J$200,0))),"") | H7: =IFERROR(IF(INDEX(Zuteilungen!$H$2:$H$200,MATCH(3,Zuteilungen!$J$2:$J$200,0))="","",INDEX(Zuteilungen!$H$2:$H$200,MATCH(3,Zuteilungen!$J$2:$J$200,0))),"") | I7: =IFERROR(IF(INDEX(Zuteilungen!$I$2:$I$200,MATCH(3,Zuteilungen!$J$2:$J$200,0))="","",INDEX(Zuteilungen!$I$2:$I$200,MATCH(3,Zuteilungen!$J$2:$J$200,0))),"")
A8: =IFERROR(IF(MATCH(4,Zuteilungen!$J$2:$J$200,0)>0,4,""),"") | B8: =IFERROR(IF(INDEX(Zuteilungen!$A$2:$A$200,MATCH(4,Zuteilungen!$J$2:$J$200,0))="","",INDEX(Zuteilungen!$A$2:$A$200,MATCH(4,Zuteilungen!$J$2:$J$200,0))),"") | C8: =IFERROR(IF(INDEX(Zuteilungen!$B$2:$B$200,MATCH(4,Zuteilungen!$J$2:$J$200,0))="","",INDEX(Zuteilungen!$B$2:$B$200,MATCH(4,Zuteilungen!$J$2:$J$200,0))),"") | D8: =IFERROR(IF(INDEX(Zuteilungen!$C$2:$C$200,MATCH(4,Zuteilungen!$J$2:$J$200,0))="","",INDEX(Zuteilungen!$C$2:$C$200,MATCH(4,Zuteilungen!$J$2:$J$200,0))),"") | E8: =IFERROR(IF(INDEX(Zuteilungen!$D$2:$D$200,MATCH(4,Zuteilungen!$J$2:$J$200,0))="","",INDEX(Zuteilungen!$D$2:$D$200,MATCH(4,Zuteilungen!$J$2:$J$200,0))),"") | F8: =IFERROR(IF(INDEX(Zuteilungen!$E$2:$E$200,MATCH(4,Zuteilungen!$J$2:$J$200,0))="","",INDEX(Zuteilungen!$E$2:$E$200,MATCH(4,Zuteilungen!$J$2:$J$200,0))),"") | G8: =IFERROR(IF(INDEX(Zuteilungen!$F$2:$F$200,MATCH(4,Zuteilungen!$J$2:$J$200,0))="","",INDEX(Zuteilungen!$F$2:$F$200,MATCH(4,Zuteilungen!$J$2:$J$200,0))),"") | H8: =IFERROR(IF(INDEX(Zuteilungen!$H$2:$H$200,MATCH(4,Zuteilungen!$J$2:$J$200,0))="","",INDEX(Zuteilungen!$H$2:$H$200,MATCH(4,Zuteilungen!$J$2:$J$200,0))),"") | I8: =IFERROR(IF(INDEX(Zuteilungen!$I$2:$I$200,MATCH(4,Zuteilungen!$J$2:$J$200,0))="","",INDEX(Zuteilungen!$I$2:$I$200,MATCH(4,Zuteilungen!$J$2:$J$200,0))),"")
A9: =IFERROR(IF(MATCH(5,Zuteilungen!$J$2:$J$200,0)>0,5,""),"") | B9: =IFERROR(IF(INDEX(Zuteilungen!$A$2:$A$200,MATCH(5,Zuteilungen!$J$2:$J$200,0))="","",INDEX(Zuteilungen!$A$2:$A$200,MATCH(5,Zuteilungen!$J$2:$J$200,0))),"") | C9: =IFERROR(IF(INDEX(Zuteilungen!$B$2:$B$200,MATCH(5,Zuteilungen!$J$2:$J$200,0))="","",INDEX(Zuteilungen!$B$2:$B$200,MATCH(5,Zuteilungen!$J$2:$J$200,0))),"") | D9: =IFERROR(IF(INDEX(Zuteilungen!$C$2:$C$200,MATCH(5,Zuteilungen!$J$2:$J$200,0))="","",INDEX(Zuteilungen!$C$2:$C$200,MATCH(5,Zuteilungen!$J$2:$J$200,0))),"") | E9: =IFERROR(IF(INDEX(Zuteilungen!$D$2:$D$200,MATCH(5,Zuteilungen!$J$2:$J$200,0))="","",INDEX(Zuteilungen!$D$2:$D$200,MATCH(5,Zuteilungen!$J$2:$J$200,0))),"") | F9: =IFERROR(IF(INDEX(Zuteilungen!$E$2:$E$200,MATCH(5,Zuteilungen!$J$2:$J$200,0))="","",INDEX(Zuteilungen!$E$2:$E$200,MATCH(5,Zuteilungen!$J$2:$J$200,0))),"") | G9: =IFERROR(IF(INDEX(Zuteilungen!$F$2:$F$200,MATCH(5,Zuteilungen!$J$2:$J$200,0))="","",INDEX(Zuteilungen!$F$2:$F$200,MATCH(5,Zuteilungen!$J$2:$J$200,0))),"") | H9: =IFERROR(IF(INDEX(Zuteilungen!$H$2:$H$200,MATCH(5,Zuteilungen!$J$2:$J$200,0))="","",INDEX(Zuteilungen!$H$2:$H$200,MATCH(5,Zuteilungen!$J$2:$J$200,0))),"") | I9: =IFERROR(IF(INDEX(Zuteilungen!$I$2:$I$200,MATCH(5,Zuteilungen!$J$2:$J$200,0))="","",INDEX(Zuteilungen!$I$2:$I$200,MATCH(5,Zuteilungen!$J$2:$J$200,0))),"")
A10: =IFERROR(IF(MATCH(6,Zuteilungen!$J$2:$J$200,0)>0,6,""),"") | B10: =IFERROR(IF(INDEX(Zuteilungen!$A$2:$A$200,MATCH(6,Zuteilungen!$J$2:$J$200,0))="","",INDEX(Zuteilungen!$A$2:$A$200,MATCH(6,Zuteilungen!$J$2:$J$200,0))),"") | C10: =IFERROR(IF(INDEX(Zuteilungen!$B$2:$B$200,MATCH(6,Zuteilungen!$J$2:$J$200,0))="","",INDEX(Zuteilungen!$B$2:$B$200,MATCH(6,Zuteilungen!$J$2:$J$200,0))),"") | D10: =IFERROR(IF(INDEX(Zuteilungen!$C$2:$C$200,MATCH(6,Zuteilungen!$J$2:$J$200,0))="","",INDEX(Zuteilungen!$C$2:$C$200,MATCH(6,Zuteilungen!$J$2:$J$200,0))),"") | E10: =IFERROR(IF(INDEX(Zuteilungen!$D$2:$D$200,MATCH(6,Zuteilungen!$J$2:$J$200,0))="","",INDEX(Zuteilungen!$D$2:$D$200,MATCH(6,Zuteilungen!$J$2:$J$200,0))),"") | F10: =IFERROR(IF(INDEX(Zuteilungen!$E$2:$E$200,MATCH(6,Zuteilungen!$J$2:$J$200,0))="","",INDEX(Zuteilungen!$E$2:$E$200,MATCH(6,Zuteilungen!$J$2:$J$200,0))),"") | G10: =IFERROR(IF(INDEX(Zuteilungen!$F$2:$F$200,MATCH(6,Zuteilungen!$J$2:$J$200,0))="","",INDEX(Zuteilungen!$F$2:$F$200,MATCH(6,Zuteilungen!$J$2:$J$200,0))),"") | H10: =IFERROR(IF(INDEX(Zuteilungen!$H$2:$H$200,MATCH(6,Zuteilungen!$J$2:$J$200,0))="","",INDEX(Zuteilungen!$H$2:$H$200,MATCH(6,Zuteilungen!$J$2:$J$200,0))),"") | I10: =IFERROR(IF(INDEX(Zuteilungen!$I$2:$I$200,MATCH(6,Zuteilungen!$J$2:$J$200,0))="","",INDEX(Zuteilungen!$I$2:$I$200,MATCH(6,Zuteilungen!$J$2:$J$200,0))),"")
A11: =IFERROR(IF(MATCH(7,Zuteilungen!$J$2:$J$200,0)>0,7,""),"") | B11: =IFERROR(IF(INDEX(Zuteilungen!$A$2:$A$200,MATCH(7,Zuteilungen!$J$2:$J$200,0))="","",INDEX(Zuteilungen!$A$2:$A$200,MATCH(7,Zuteilungen!$J$2:$J$200,0))),"") | C11: =IFERROR(IF(INDEX(Zuteilungen!$B$2:$B$200,MATCH(7,Zuteilungen!$J$2:$J$200,0))="","",INDEX(Zuteilungen!$B$2:$B$200,MATCH(7,Zuteilungen!$J$2:$J$200,0))),"") | D11: =IFERROR(IF(INDEX(Zuteilungen!$C$2:$C$200,MATCH(7,Zuteilungen!$J$2:$J$200,0))="","",INDEX(Zuteilungen!$C$2:$C$200,MATCH(7,Zuteilungen!$J$2:$J$200,0))),"") | E11: =IFERROR(IF(INDEX(Zuteilungen!$D$2:$D$200,MATCH(7,Zuteilungen!$J$2:$J$200,0))="","",INDEX(Zuteilungen!$D$2:$D$200,MATCH(7,Zuteilungen!$J$2:$J$200,0))),"") | F11: =IFERROR(IF(INDEX(Zuteilungen!$E$2:$E$200,MATCH(7,Zuteilungen!$J$2:$J$200,0))="","",INDEX(Zuteilungen!$E$2:$E$200,MATCH(7,Zuteilungen!$J$2:$J$200,0))),"") | G11: =IFERROR(IF(INDEX(Zuteilungen!$F$2:$F$200,MATCH(7,Zuteilungen!$J$2:$J$200,0))="","",INDEX(Zuteilungen!$F$2:$F$200,MATCH(7,Zuteilungen!$J$2:$J$200,0))),"") | H11: =IFERROR(IF(INDEX(Zuteilungen!$H$2:$H$200,MATCH(7,Zuteilungen!$J$2:$J$200,0))="","",INDEX(Zuteilungen!$H$2:$H$200,MATCH(7,Zuteilungen!$J$2:$J$200,0))),"") | I11: =IFERROR(IF(INDEX(Zuteilungen!$I$2:$I$200,MATCH(7,Zuteilungen!$J$2:$J$200,0))="","",INDEX(Zuteilungen!$I$2:$I$200,MATCH(7,Zuteilungen!$J$2:$J$200,0))),"")
